<?xml version="1.0"?>
<robot name="my_robot">

  <!-- Base Link -->
  <link name="base_link">
    <visual>
      <geometry>
        <box size="0.5 0.3 0.2"/>
      </geometry>
      <material name="orange"/>
    </visual>
  </link>

  <!-- Wheel Links -->
  <link name="left_wheel"/>
  <link name="right_wheel"/>

  <!-- Laser Scanner -->
  <link name="laser">
    <visual>
      <geometry>
        <cylinder length="0.1" radius="0.05"/>
      </geometry>
      <material name="black"/>
    </visual>
  </link>

  <!-- Joints (simplified, non-functional) -->
  <joint name="left_wheel_joint" type="continuous">
    <parent link="base_link"/>
    <child link="left_wheel"/>
    <origin xyz="0.2 -0.15 0" rpy="0 0 0"/>
  </joint>
  <joint name="right_wheel_joint" type="continuous">
    <parent link="base_link"/>
    <child link="right_wheel"/>
    <origin xyz="0.2 0.15 0" rpy="0 0 0"/>
  </joint>
  <joint name="laser_joint" type="fixed">
    <parent link="base_link"/>
    <child link="laser"/>
    <origin xyz="0.25 0 0.15" rpy="0 0 0"/>
  </joint>

</robot>
