<?xml version="1.0"?>
<robot name="my_robot" xmlns:xacro="http://www.ros.org/wiki/xacro">
  
  <!-- Constants for robot dimensions -->
  <xacro:property name="wheel_radius" value="0.06"/>
  <xacro:property name="wheel_width" value="0.02"/>
  <xacro:property name="chassis_radius" value="0.3"/>
  <xacro:property name="chassis_height" value="0.1"/>
  <link name="base_footprint">
  <inertial>
    <mass value="0.0"/>
    <inertia ixx="0.0" ixy="0.0" ixz="0.0" iyy="0.0" iyz="0.0" izz="0.0"/>
  </inertial>
</link>
  <!-- Base Link -->
  <link name="base_link">
    <visual>
      <geometry>
        <cylinder radius="${chassis_radius}" length="${chassis_height}"/>
      </geometry>
      <material name="blue">
        <color rgba="0.0 0.0 1.0 1.0"/>
      </material>
    </visual>

    <collision>
      <geometry>
        <cylinder radius="${chassis_radius}" length="${chassis_height}"/>
      </geometry>
    </collision>

    <inertial>
      <mass value="10.0"/>
      <inertia 
        ixx="0.05" ixy="0.0" ixz="0.0"
        iyy="0.05" iyz="0.0"
        izz="0.1"/>
    </inertial>
  </link>

  <!-- Left Wheel -->
  <link name="left_wheel">
    <visual>
      <geometry>
        <cylinder radius="${wheel_radius}" length="${wheel_width}"/>
      </geometry>
      <material name="black"/>
    </visual>

    <collision>
      <geometry>
        <cylinder radius="${wheel_radius}" length="${wheel_width}"/>
      </geometry>
    </collision>

    <inertial>
      <mass value="1.0"/>
      <inertia 
        ixx="0.001" ixy="0.0" ixz="0.0"
        iyy="0.001" iyz="0.0"
        izz="0.001"/>
    </inertial>
  </link>


  <!-- Right Wheel -->
  <link name="right_wheel">
    <visual>
      <geometry>
        <cylinder radius="${wheel_radius}" length="${wheel_width}"/>
      </geometry>
      <material name="black"/>
    </visual>

    <collision>
      <geometry>
        <cylinder radius="${wheel_radius}" length="${wheel_width}"/>
      </geometry>
    </collision>

    <inertial>
      <mass value="1.0"/>
      <inertia 
        ixx="0.001" ixy="0.0" ixz="0.0"
        iyy="0.001" iyz="0.0"
        izz="0.001"/>
    </inertial>
  </link>
  <!-- Front Wheel -->
  <link name="front_wheel">
  <visual>
    <geometry>
      <sphere radius="0.025"/>
    </geometry>
    <material name="black"/>
  </visual>

  <collision>
    <geometry>
      <sphere radius="0.025"/>
    </geometry>
  </collision>

  <inertial>
    <mass value="1.0"/>
    <inertia 
      ixx="0.001" ixy="0.0" ixz="0.0"
      iyy="0.001" iyz="0.0"
      izz="0.001"/>
  </inertial>
</link>

  <link name="lidar_link">
    <visual>
      <geometry>
        <box size="0.1 0.1 0.05"/> <!-- Size to be adjusted -->
      </geometry>
    </visual>
    <inertial>
      <mass value="1.0"/> <!-- Adjust mass -->
      <inertia ixx="0.001" ixy="0" ixz="0" iyy="0.001" iyz="0" izz="0.001"/> <!-- Adjust inertia -->
    </inertial>
  </link>


  <!-- Joints -->
  <joint name="base_footprint_joint" type="fixed">
  <parent link="base_link"/>
  <child link="base_footprint"/>
  <origin xyz="0 -0.2 0" rpy="0 0 0"/> <!-- Adjust the origin if necessary -->
</joint>
  <!-- Left Wheel Joint -->
  <joint name="left_wheel_joint" type="continuous">
    <parent link="base_link"/>
    <child link="left_wheel"/>
    <origin xyz="0.0 0.3 -0.02" rpy="1.5707 0 0"/>
    <axis xyz="0 0 1"/>
  </joint>

  <!-- Right Wheel Joint -->
  <joint name="right_wheel_joint" type="continuous">
    <parent link="base_link"/>
    <child link="right_wheel"/>
    <origin xyz="0 -0.3 -0.02" rpy="1.5707 0 0"/>
    <axis xyz="0 0 1"/>
  </joint>


  <!-- Front Joint -->
  <joint name="front_wheel_joint" type="fixed">
    <parent link="base_link"/>
    <child link="front_wheel"/>
    <origin xyz="-0.25 0 -0.055" rpy="0 0 0"/> <!-- Adjust xyz as per the desired position -->
  </joint>


  <!-- Servo Motor Joint -->
  <joint name="servo_joint" type="revolute">
    <parent link="base_link"/>
    <child link="lidar_link"/>
    <origin xyz="0 0 0.1" rpy="0 0 0"/> <!-- Position to be adjusted -->
    <axis xyz="1 0 0"/>
    <limit lower="-1.57" upper="1.57" effort="5" velocity="1"/>
  </joint>

  <!-- Lidar Joint
  <joint name="lidar_joint" type="fixed">
    <parent link="base_link"/>
    <child link="lidar_link"/>

    <origin xyz="0 0 0.1" rpy="0 0 0"/>
  </joint> -->



<!-- Lidar Link -->
<!-- <link name="lidar_link">
  <visual>
    <geometry>
      <cylinder length="0.1" radius="${wheel_radius}"/>
    </geometry>
  </visual>
</link> -->



  <!-- Transmission for wheels -->
  <transmission name="left_wheel_trans">
    <type>transmission_interface/SimpleTransmission</type>
    <joint name="left_wheel_joint">
      <hardwareInterface>VelocityJointInterface</hardwareInterface>
    </joint>
    <actuator name="left_wheel_motor">
      <hardwareInterface>VelocityJointInterface</hardwareInterface>
      <mechanicalReduction>1</mechanicalReduction>
    </actuator>
  </transmission>

<transmission name="right_wheel_trans">
    <type>transmission_interface/SimpleTransmission</type>
    <joint name="right_wheel_joint">
      <hardwareInterface>VelocityJointInterface</hardwareInterface>
    </joint>
    <actuator name="right_wheel_motor">
      <hardwareInterface>VelocityJointInterface</hardwareInterface>
      <mechanicalReduction>1</mechanicalReduction>
    </actuator>
  </transmission>
  <!-- Transmission for Servo Motor -->
<transmission name="servo_transmission">
  <type>transmission_interface/SimpleTransmission</type>
  <joint name="servo_joint">
    <hardwareInterface>PositionJointInterface</hardwareInterface>
  </joint>
  <actuator name="servo_motor">
    <hardwareInterface>PositionJointInterface</hardwareInterface>
    <mechanicalReduction>1</mechanicalReduction>
  </actuator>
</transmission>

<gazebo>
    <plugin name="gazebo_ros_control" filename="libgazebo_ros_control.so">
      <robotNamespace>/</robotNamespace>
      <!-- <robotSimType>gazebo_ros_control/DefaultRobotHWSim</robotSimType>
      <legacyModeNS>true</legacyModeNS> -->
      <robotParam>robot_description</robotParam>
      <controller name=" diff_drive_controller servo_controller"/>
    </plugin>
    <plugin name="p3d_base_controller" filename="libgazebo_ros_p3d.so">
      <alwaysOn>true</alwaysOn>
      <updateRate>50.0</updateRate>
      <bodyName>base_link</bodyName>
      <topicName>world</topicName>
      <publishOdomTF>true</publishOdomTF>
      <publishTf>true</publishTf>
      <gaussianNoise>0.01</gaussianNoise>
      <frameName>world</frameName>
      <xyzOffsets>0 0 0</xyzOffsets>
      <rpyOffsets>0 0 0</rpyOffsets>
</plugin>
  </gazebo>

<gazebo reference="lidar_link">
  
  <sensor type="ray" name="lidar_sensor">
    <pose>0 0 0 0 0 0</pose>
    <visualize>true</visualize>
    <update_rate>10</update_rate>
    <ray>
      <scan>
        <horizontal>
          <samples>720</samples>
          <resolution>1</resolution>
          <min_angle>-3.14</min_angle>
          <max_angle>3.14</max_angle>
        </horizontal>
      </scan>
      <range>
        <min>0.1</min>
        <max>12</max>
        <resolution>0.01</resolution>
      </range>
    </ray>
    <plugin name="gazebo_ros_laser_controller" filename="libgazebo_ros_laser.so">
      <topicName>/scan</topicName>
      <frameName>lidar_link</frameName>
    </plugin>
  </sensor>
</gazebo>
</robot>