<?xml version="1.0"?>
<robot name="my_robot" xmlns:xacro="http://www.ros.org/wiki/xacro">
  
  <!-- Constants for robot dimensions -->
  <xacro:property name="wheel_radius" value="0.06"/>
  <xacro:property name="wheel_width" value="0.02"/>
  <xacro:property name="chassis_radius" value="0.3"/>
  <xacro:property name="chassis_height" value="0.1"/>

  <!-- Base Link -->
  <link name="base_link">
    <visual>
      <geometry>
        <cylinder radius="${chassis_radius}" length="${chassis_height}"/>
      </geometry>
      <material name="blue">
        <color rgba="0.0 0.0 1.0 1.0"/>
      </material>
    </visual>

    <collision>
      <geometry>
        <cylinder radius="${chassis_radius}" length="${chassis_height}"/>
      </geometry>
    </collision>

    <inertial>
      <mass value="10.0"/>
      <inertia 
        ixx="0.05" ixy="0.0" ixz="0.0"
        iyy="0.05" iyz="0.0"
        izz="0.1"/>
    </inertial>
  </link>

  <!-- Left Wheel -->
  <link name="left_wheel">
    <visual>
      <geometry>
        <cylinder radius="${wheel_radius}" length="${wheel_width}"/>
      </geometry>
      <material name="black"/>
    </visual>

    <collision>
      <geometry>
        <cylinder radius="${wheel_radius}" length="${wheel_width}"/>
      </geometry>
    </collision>

    <inertial>
      <mass value="1.0"/>
      <inertia 
        ixx="0.001" ixy="0.0" ixz="0.0"
        iyy="0.001" iyz="0.0"
        izz="0.001"/>
    </inertial>
  </link>

  <!-- Right Wheel -->
  <link name="right_wheel">
    <visual>
      <geometry>
        <cylinder radius="${wheel_radius}" length="${wheel_width}"/>
      </geometry>
      <material name="black"/>
    </visual>

    <collision>
      <geometry>
        <cylinder radius="${wheel_radius}" length="${wheel_width}"/>
      </geometry>
    </collision>

    <inertial>
      <mass value="1.0"/>
      <inertia 
        ixx="0.001" ixy="0.0" ixz="0.0"
        iyy="0.001" iyz="0.0"
        izz="0.001"/>
    </inertial>
  </link>
<!-- Dummy Wheel  -->

<link name="dummy_wheel">
  <visual>
    <geometry>
      <cylinder length="0.02" radius="0.03"/>
    </geometry>
    <material name="black"/>
  </visual>
  <collision>
    <geometry>
      <cylinder length="0.1" radius="0.05"/>
    </geometry>
  </collision>
  <inertial>
    <mass value="1.0"/>
    <inertia ixx="0.01" ixy="0.0" ixz="0.0" iyy="0.01" iyz="0.0" izz="0.02"/>
  </inertial>
</link>

  <!-- Joints -->
  <!-- Left Wheel Joint -->
  <joint name="left_wheel_joint" type="continuous">
    <parent link="base_link"/>
    <child link="left_wheel"/>
    <origin xyz="0.0 0.3 -0.02" rpy="1.5707 0 0"/>
    <axis xyz="0 0 1"/>
  </joint>

  <!-- Right Wheel Joint -->
  <joint name="right_wheel_joint" type="continuous">
    <parent link="base_link"/>
    <child link="right_wheel"/>
    <origin xyz="0 -0.3 -0.02" rpy="1.5707 0 0"/>
    <axis xyz="0 0 1"/>
  </joint>
  <!-- Dummy Wheel Joinr  -->

<joint name="dummy_wheel_joint" type="fixed">
  <parent link="base_link"/>
  <child link="dummy_wheel"/>
  <origin xyz="0.25 0 -0.04" rpy="1.5707 0 -0.02"/>
</joint>
  <!-- Transmission for wheels -->
  <transmission name="left_wheel_trans">
    <type>transmission_interface/SimpleTransmission</type>
    <joint name="left_wheel_joint">
      <hardwareInterface>VelocityJointInterface</hardwareInterface>
    </joint>
    <actuator name="left_wheel_motor">
      <hardwareInterface>VelocityJointInterface</hardwareInterface>
      <mechanicalReduction>1</mechanicalReduction>
    </actuator>
  </transmission>

<transmission name="right_wheel_trans">
    <type>transmission_interface/SimpleTransmission</type>
    <joint name="right_wheel_joint">
      <hardwareInterface>VelocityJointInterface</hardwareInterface>
    </joint>
    <actuator name="right_wheel_motor">
      <hardwareInterface>VelocityJointInterface</hardwareInterface>
      <mechanicalReduction>1</mechanicalReduction>
    </actuator>
  </transmission>
<gazebo>
    <plugin name="gazebo_ros_control" filename="libgazebo_ros_control.so">
      <robotNamespace>/</robotNamespace>
      <!-- <robotSimType>gazebo_ros_control/DefaultRobotHWSim</robotSimType>
      <legacyModeNS>true</legacyModeNS> -->
      <robotParam>robot_description</robotParam>
      <controller name=" left_wheel_controller right_wheel_controller"/>
    </plugin>
    <plugin name="p3d_base_controller" filename="libgazebo_ros_p3d.so">
      <alwaysOn>true</alwaysOn>
      <updateRate>50.0</updateRate>
      <bodyName>base_link</bodyName>
      <topicName>odom</topicName>
      <publishOdomTF>true</publishOdomTF>
      <publishTf>true</publishTf>
      <gaussianNoise>0.01</gaussianNoise>
      <frameName>world</frameName>
      <xyzOffsets>0 0 0</xyzOffsets>
      <rpyOffsets>0 0 0</rpyOffsets>
</plugin>
  </gazebo>
</robot>